---
title:  "C# chapter10: 예외 처리"
excerpt: "예외 처리에 대해 알아보자"

categories:
  - C sharp


toc: true
toc_sticky: true

date: 2022-05-07
last_modified_at: 2022-05-07
---
[예제로 배우는 C#프로그래밍](http://www.csharpstudy.com/CSharp/CSharp-exception.aspx)에서 참고했습니다.

## C# Exception 예외 처리

  - c#을 포함한 모든 .NET 프로그래밍 언어는 .NET Framework의 Exception 메커님즈에 따라 Exception을 처리한다.
  - `.NET의 System.Exception`은 모든 Exception 의 Base 클래스이며, 예외 처리는 이 Exception 객체를 기본으로 처리하게 된다.

  - C#에서는 `try, catch, finally`라는 키워드를 사용하여 Exception을 핸들링 하게 되며 또한 throw 라는 c# 키워드를 통해 Exception을 만들어 던지거나 혹은 기존 Exception을 다시 던질 수 있다.

  ```c#
  try{
    DoSomething(); // 실행하고자 하는 문장
  }
  catch (Exception ex){
    //에러 처리/로깅 등
    Log(ex);
    throw;
  }
  ```

  - `finally`는 Exception이 발생했던 안했던 상관없이 마지막에 반드시 실행되는 블럭이다.

  ```c#
  try{
    //실행 문장
  }
  catch (ArgumentException ex){
    //Argument 예외처리
  }
  catch (AccessViolationException ex){
    //AcessViolation 예외처리
  }
  finally{
    //마지막으로 실행하는 문장
  }
  ```

## C# throw

  - try 블럭에서 Exception이 발생하였는데 이를 catch 문에서 잡었다면, Exception은 이미 처리된 것으로 간주된다.
  - catch문에서 기존의 Exception을 다시 상위 호출자로 보내고 싶을 때가 있는데, 이때 `throw` 를 사용한다.

  (1) throw 문 다음에 catch에서 전달받은 Exception 객체를 쓰는 경우
  이는 `throw ex;` 와 같이 catch (Exception ex) 에서 전달받은 아규먼트 ex 를 사용하는 경우이다. 이러한 throw 방식은 ex 에 담긴 예외 정보를 보전하지만, Stack Trace 정보를 다시 리셋하기 때문에 throw문 이전의 콜스택(Call Stack) 정보를 유실하게 된다. 따라서, 일반적으로 이러한 방식은 사용하지 않는 것이 좋다.

  (2) throw 문 다음에 새 Exception 객체를 생성해서 전달하는 경우
  새로운 Exception 객체를 만들어 던지기 위해서는 `throw new MyException();`와 같이 C#의 new를 사용하여 새로운 Exception 객체를 만든 후, 이 객체를 throw 하면 된다. 이는 catch 에서 잡은 Exception을 Wrapping 하여 새로운 Exception을 전달할 때 사용하는데, 잘못 사용하면(InnerException을 포함하지 않으면) 기존 Exception 정보를 잃을 수 있다.
  따라서, 이러한 방식을 사용하여 새로운 Exception 객체를 만들 때는 catch 에서 얻은 Exception 객체를 새 객체의 InnerException에 포함시켜 에러 정보를 보전하는 것이 좋다. 예를 들어, throw new MyException(msg, ex); 와 같이 catch에서 전달받은 ex를 InnerException으로 전달하는 것이 좋다. InnerException의 StackTrace 속성은 어느 라인에서 에러가 발생했는지를 알려주는데, 이는 에러가 다른 메서드에서 발생했을 때는 물론 동일 메서드에서 발생했다 하더라도 정확히 어떤 라인에서 에러가 발생했는지를 알게 해 준다.

  (3) throw 문 다음에 아무것도 없는 경우
  `throw;` 와 같이 뒤에 어떠한 Exception 객체 없이 그냥 throw문만을 사용할 수 있는데, 이는 catch문에서 잡힌 Exception을 그대로 상위 호출 함수에게 전달하는 일(rethrow)을 한다. 즉, 에러를 발생시킨 콜스택 정보를 그대로 상위 호출 함수에 전달하려면 이렇게 throw; 를 호출하면 된다. 한가지 주목할 점은, throw; 는 에러가 다른 메서드에서 발생했을 때는 그 에러가 발생한 다른 메서드의 위치를 포함하지만, 만약 throw문과 동일한 메서드에서 에러가 발생했다면 동일 메서드의 어느 라인에서 에러가 발생했는지는 포함하지 않는다.

  ```c#
  try
  {
      // 실행 문장들
      Step1();
      Step2();
      Step3();
  }
  catch(IndexOutOfRangeException ex)
  {
      // 새로운 Exception 생성하여 throw
      throw new MyException("Invalid index", ex);
  }
  catch(FileNotFoundException ex)
  {    
      bool success = Log(ex);
      if (!success)
      {
          // 기존 Exception을 throw
          throw ex;
      }
  }
  catch(Exception ex)
  {    
      Log(ex);
      // 발생된 Exception을 그대로 호출자에 전달
      throw;
  }
  ```
